Workbook
Name Slicer_Year: #N/A

Sheet Cover Page

Sheet Table of Content
B1: Scenario: | K1: Last Updated: | L1: =TODAY() -> 45934
B3: Table of Content
B5: SN | C5: Details
B6: 1 | C6: Summary
B7: 2 | C7: Dashboard
B8: 3 | C8: Assumptions
B9: 4 | C9: Workings
B10: 5 | C10: Income Statement
B11: 6 | C11: Balance Sheet
B12: 7 | C12: Cashflow Statement
B13: 8 | C13: Valuation
B14: 9 | C14: Financial Ratios
B15: 10 | C15: Data Page

Sheet Summary Page
B1: Scenario: | M1: Last Updated: | N1: =TODAY() -> 45934 | O1: Back
C5: Company Name: | F5: Ling Tao Holdings
C6: Sector: | F6: Real Estate
C8: Equity Investment | G8: =Workings!I87 -> 5392069.9
C9: Enterprise Value | G9: =Valuation!I27 -> 15826181
C10: Equity Valuation | G10: =Valuation!I51 -> 11319075
G12: 2026 | H12: =G12+1 -> 2027 | I12: =H12+1 -> 2028 | J12: =I12+1 -> 2029 | K12: =J12+1 -> 2030
C13: Income Statement
D14: Revenue | G14: ='Income Statement'!I6 -> 6327360 | H14: ='Income Statement'!J6 -> 6503243.1 | I14: ='Income Statement'!K6 -> 6591808.7 | J14: ='Income Statement'!L6 -> 6680374.3 | K14: ='Income Statement'!M6 -> 6768939.8
D15: Cost of Sales | G15: =-'Income Statement'!I7 -> 3096942.7 | H15: =-'Income Statement'!J7 -> 3030787 | I15: =-'Income Statement'!K7 -> 2921286 | J15: =-'Income Statement'!L7 -> 2784409.7 | K15: =-'Income Statement'!M7 -> 2613314.4
D16: Gross Profit | G16: ='Income Statement'!I9 -> 3230417.3 | H16: ='Income Statement'!J9 -> 3472456.1 | I16: ='Income Statement'!K9 -> 3670522.7 | J16: ='Income Statement'!L9 -> 3895964.5 | K16: ='Income Statement'!M9 -> 4155625.5
D17: Operating Expenses | G17: =-'Income Statement'!I11 -> 1544283.2 | H17: =-'Income Statement'!J11 -> 885389.18 | I17: =-'Income Statement'!K11 -> 902017.04 | J17: =-'Income Statement'!L11 -> 885243.04 | K17: =-'Income Statement'!M11 -> 895428.08
D18: Operating Income | G18: ='Income Statement'!I13 -> 1686134.1 | H18: ='Income Statement'!J13 -> 2587066.9 | I18: ='Income Statement'!K13 -> 2768505.6 | J18: ='Income Statement'!L13 -> 3010721.5 | K18: ='Income Statement'!M13 -> 3260197.4
D19: Profit before Tax | G19: ='Income Statement'!I17 -> 1579693 | H19: ='Income Statement'!J17 -> 2417861 | I19: ='Income Statement'!K17 -> 2516197.5 | J19: ='Income Statement'!L17 -> 2677951.8 | K19: ='Income Statement'!M17 -> 2825016.9
D20: Net Profit | G20: ='Income Statement'!I21 -> 1184769.7 | H20: ='Income Statement'!J21 -> 1813395.8 | I20: ='Income Statement'!K21 -> 1887148.1 | J20: ='Income Statement'!L21 -> 2008463.8 | K20: ='Income Statement'!M21 -> 2118762.7
C22: Balance Sheet
D23: Non-Current Assets | G23: ='Balance Sheet'!I13 -> 5137794.5 | H23: ='Balance Sheet'!J13 -> 4857530.2 | I23: ='Balance Sheet'!K13 -> 4551788.5 | J23: ='Balance Sheet'!L13 -> 4125366.1 | K23: ='Balance Sheet'!M13 -> 3647259.1
D24: Current Assets | G24: ='Balance Sheet'!I17 -> 5184927.6 | H24: ='Balance Sheet'!J17 -> 6704475.7 | I24: ='Balance Sheet'!K17 -> 7874889.1 | J24: ='Balance Sheet'!L17 -> 9117307.5 | K24: ='Balance Sheet'!M17 -> 10279905
D25: Total Asset | G25: ='Balance Sheet'!I13+'Balance Sheet'!I17 -> 10322722 | H25: ='Balance Sheet'!J13+'Balance Sheet'!J17 -> 11562006 | I25: ='Balance Sheet'!K13+'Balance Sheet'!K17 -> 12426678 | J25: ='Balance Sheet'!L13+'Balance Sheet'!L17 -> 13242674 | K25: ='Balance Sheet'!M13+'Balance Sheet'!M17 -> 13927164
D27: Total Equity | G27: ='Balance Sheet'!I33 -> 6339885.7 | H27: ='Balance Sheet'!J33 -> 7790602.3 | I27: ='Balance Sheet'!K33 -> 9300320.8 | J27: ='Balance Sheet'!L33 -> 10907092 | K27: ='Balance Sheet'!M33 -> 12602102
D28: Non-Current Liabilities | G28: ='Balance Sheet'!I38 -> 3156709.2 | H28: ='Balance Sheet'!J38 -> 2609204.1 | I28: ='Balance Sheet'!K38 -> 1924822.7 | J28: ='Balance Sheet'!L38 -> 0 | K28: ='Balance Sheet'!M38 -> 0
D29: Current Liabilities | G29: ='Balance Sheet'!I24 -> 826127.18 | H29: ='Balance Sheet'!J24 -> 1162199.5 | I29: ='Balance Sheet'!K24 -> 1201534.1 | J29: ='Balance Sheet'!L24 -> 2335581.8 | K29: ='Balance Sheet'!M24 -> 1325061.9
D30: Total Equity & Liabilities | G30: ='Balance Sheet'!I33+'Balance Sheet'!I38+'Balance Sheet'!I24 -> 10322722 | H30: ='Balance Sheet'!J33+'Balance Sheet'!J38+'Balance Sheet'!J24 -> 11562006 | I30: ='Balance Sheet'!K33+'Balance Sheet'!K38+'Balance Sheet'!K24 -> 12426678 | J30: ='Balance Sheet'!L33+'Balance Sheet'!L38+'Balance Sheet'!L24 -> 13242674 | K30: ='Balance Sheet'!M33+'Balance Sheet'!M38+'Balance Sheet'!M24 -> 13927164
C32: Cash Flow Statement
D33: Cash flow from operating activities | G33: ='Cashflow Statement'!I18 -> 2405076.8 | H33: ='Cashflow Statement'!J18 -> 3453235.5 | I33: ='Cashflow Statement'!K18 -> 3314826.1 | J33: ='Cashflow Statement'!L18 -> 3395581.5 | K33: ='Cashflow Statement'!M18 -> 3433523.5
D34: Cash flow from investing activities | G34: ='Cashflow Statement'!I23 -> -4870250 | H34: ='Cashflow Statement'!J23 -> -360051.06 | I34: ='Cashflow Statement'!K23 -> -445051.06 | J34: ='Cashflow Statement'!L23 -> -439051.06 | K34: ='Cashflow Statement'!M23 -> -532551.06
D35: Cash flow from financing activities | G35: ='Cashflow Statement'!I31 -> 7650100.8 | H35: ='Cashflow Statement'!J31 -> -1573636.4 | I35: ='Cashflow Statement'!K31 -> -1699361.6 | J35: ='Cashflow Statement'!L31 -> -1714112 | K35: ='Cashflow Statement'!M31 -> -1738375.2
D36: Net cash flow | G36: ='Cashflow Statement'!I35 -> 5184927.6 | H36: ='Cashflow Statement'!J35 -> 6704475.7 | I36: ='Cashflow Statement'!K35 -> 7874889.1 | J36: ='Cashflow Statement'!L35 -> 9117307.5 | K36: ='Cashflow Statement'!M35 -> 10279905
D37: Net cash flow to firm | G37: =Valuation!I17 -> -3099280.4 | H37: =Valuation!J17 -> 2843378.4 | I37: =Valuation!K17 -> 2812575.8 | J37: =Valuation!L17 -> 2892031.6 | K37: =Valuation!M17 -> 2850839.3
C39: Financial Ratios
D40: Gross Profit margin | G40: ='Financial Ratios'!F7 -> 0.51054742 | H40: ='Financial Ratios'!G7 -> 0.5339576 | I40: ='Financial Ratios'!H7 -> 0.55683089 | J40: ='Financial Ratios'!I7 -> 0.58319555 | K40: ='Financial Ratios'!J7 -> 0.6139256
D41: Operating profit margin | G41: ='Financial Ratios'!F8 -> 0.26648304 | H41: ='Financial Ratios'!G8 -> 0.39781181 | I41: ='Financial Ratios'!H8 -> 0.41999181 | J41: ='Financial Ratios'!I8 -> 0.45068156 | K41: ='Financial Ratios'!J8 -> 0.48164077
D42: Net profit margin | G42: ='Financial Ratios'!F9 -> 0.1872455 | H42: ='Financial Ratios'!G9 -> 0.27884483 | I42: ='Financial Ratios'!H9 -> 0.28628685 | J42: ='Financial Ratios'!I9 -> 0.3006514 | K42: ='Financial Ratios'!J9 -> 0.31301248
D43: Return on Capital Equity | G43: ='Financial Ratios'!F11 -> 0.17755145 | H43: ='Financial Ratios'!G11 -> 0.24876107 | I43: ='Financial Ratios'!H11 -> 0.24663432 | J43: ='Financial Ratios'!I11 -> 0.27603339 | K43: ='Financial Ratios'!J11 -> 0.25870266
D44: Return on Asset | G44: ='Financial Ratios'!F12 -> 0.11477299 | H44: ='Financial Ratios'!G12 -> 0.15684093 | I44: ='Financial Ratios'!H12 -> 0.15186265 | J44: ='Financial Ratios'!I12 -> 0.15166604 | K44: ='Financial Ratios'!J12 -> 0.15213167
D45: Debt to Equity ratio | G45: ='Financial Ratios'!F22 -> 0.49791263 | H45: ='Financial Ratios'!G22 -> 0.33491686 | I45: ='Financial Ratios'!H22 -> 0.20696304 | J45: ='Financial Ratios'!I22 -> 0.098041342 | K45: ='Financial Ratios'!J22 -> 0
D46: Equity ratio | G46: ='Financial Ratios'!F23 -> 0.61416801 | H46: ='Financial Ratios'!G23 -> 0.67381061 | I46: ='Financial Ratios'!H23 -> 0.74841571 | J46: ='Financial Ratios'!I23 -> 0.82363216 | K46: ='Financial Ratios'!J23 -> 0.90485774
D47: Debt ratio | G47: ='Financial Ratios'!F24 -> 0.30580201 | H47: ='Financial Ratios'!G24 -> 0.22567054 | I47: ='Financial Ratios'!H24 -> 0.15489439 | J47: ='Financial Ratios'!I24 -> 0.080750002 | K47: ='Financial Ratios'!J24 -> 0
D48: Current ratio | G48: ='Financial Ratios'!F16 -> 6.2761857 | H48: ='Financial Ratios'!G16 -> 5.7687819 | I48: ='Financial Ratios'!H16 -> 6.5540286 | J48: ='Financial Ratios'!I16 -> 3.9036559 | K48: ='Financial Ratios'!J16 -> 7.7580563
D49: Quick ratio | G49: ='Financial Ratios'!F17 -> 6.2761857 | H49: ='Financial Ratios'!G17 -> 5.7687819 | I49: ='Financial Ratios'!H17 -> 6.5540286 | J49: ='Financial Ratios'!I17 -> 3.9036559 | K49: ='Financial Ratios'!J17 -> 7.7580563
...

Sheet Dashboard
Q1: Last Updated: | R1: =TODAY() -> 45934

Sheet Assumptions
B1: Scenario: | C1: 2 | K1: Last Updated: | L1: =TODAY() -> 45934 | M1: Back
B3: Assumptions
G5: 0 | H5: 1 | I5: 2 | J5: 3 | K5: 4 | L5: 5
C6: Month | H6: 12 | I6: 12 | J6: 12 | K6: 12 | L6: 12
C7: Quarter | H7: 4 | I7: 4 | J7: 4 | K7: 4 | L7: 4
C8: Inflation | H8: 0.0938 | I8: 0.08 | J8: 0.08 | K8: 0.08 | L8: 0.08 | M8: https://www.statista.com/statistics/447576/inflation-rate-in-ghana/
D11: Number of units | E11: 50 | F11: Over 5 years
D12: Sales units | E12: 0.8
D13: Rental units | E13: 0.2
D14: Retention (held till defect period) | E14: 0.1 | F14: After 1 year
D15: Other revenue (% of sales) | E15: 0.04
D16: Corporate tax | E16: 0.25
C18: Scenario
D20: Best case | E20: 1.2
D21: Base case | E21: 1
D22: Worst case | E22: 0.8
C25: Revenue Assumption
C27: Sales unit | F27: Units | H27: 8 | I27: 8 | J27: 8 | K27: 8 | L27: 8
C28: Unit price | F28: GHS | H28: 750000 | I28: =H28*(1+(H8-I8)) -> 760350 | J28: =I28*(1+(I8-J8)) -> 760350 | K28: =J28*(1+(J8-K8)) -> 760350 | L28: =K28*(1+(K8-L8)) -> 760350
C30: Rental unit | F30: Units | H30: 2 | I30: 4 | J30: 6 | K30: 8 | L30: 10
C31: Annual rent/unit | F31: GHS | H31: 42000 | I31: =H31*(1+(H8-I8)) -> 42579.6 | J31: =I31*(1+(I8-J8)) -> 42579.6 | K31: =J31*(1+(J8-K8)) -> 42579.6 | L31: =K31*(1+(K8-L8)) -> 42579.6
C34: Cost Assumption
C35: Cost per sales unit:
D36: Number of buildings | F36: Units | H36: 8 | I36: 8 | J36: 8 | K36: 8 | L36: 8
D37: Hard cost | F37: GHS | H37: 185000 | I37: =H37*(1+(H8-I8)) -> 187553 | J37: =I37*(1+(I8-J8)) -> 187553 | K37: =J37*(1+(J8-K8)) -> 187553 | L37: =K37*(1+(K8-L8)) -> 187553
D38: Soft cost (% of hard cost) | F38: % | H38: 0.05 | I38: 0.05 | J38: 0.05 | K38: 0.05 | L38: 0.05
D39: Capitalised debt arrangement fees | F39: GHS/unit | H39: 1800 | I39: 1800 | J39: 1800 | K39: 1800 | L39: 1800
D40: Land acquisition cost (acquired @ year 0) | F40: GHS/plot | H40: 101200 | I40: 101200 | J40: 101200 | K40: 101200 | L40: 101200
C45: Sellimg, General & Admin expense
C47: Property management ( % of total income) | F47: % | H47: 0.08 | I47: 0.08 | J47: 0.08 | K47: 0.08 | L47: 0.08
C48: Maintenance & repairs (% of total income) | F48: % | H48: 0.015 | I48: 0.02 | J48: 0.02 | K48: 0.02 | L48: 0.02
C49: Marketing (% of total income) | F49: % | H49: 0.025 | I49: 0.02 | J49: 0.02 | K49: 0.015 | L49: 0.015
C50: Fuel & Diesel | F50: GHS/month | H50: 5000 | I50: 5000 | J50: 5500 | K50: 6000 | L50: 6000
C51: Legal fee | F51: GHS/annum | H51: 30000 | I51: 30000 | J51: 30000 | K51: 30000 | L51: 30000
C52: Contingency | F52: GHS/annum | H52: 60000 | I52: 60000 | J52: 60000 | K52: 60000 | L52: 60000
C53: Other | F53: GHS/annum | H53: 15000 | I53: 15000 | J53: 15000 | K53: 15000 | L53: 15000
C56: Non-current Assets
C58: Cost per rental unit:
D59: Number of buildings | F59: Units | H59: 2 | I59: 2 | J59: 2 | K59: 2 | L59: 2
D60: Hard cost | F60: GHS | H60: 185000 | I60: =H60*(1+(H8-I8)) -> 187553 | J60: =I60*(1+(I8-J8)) -> 187553 | K60: =J60*(1+(J8-K8)) -> 187553 | L60: =K60*(1+(K8-L8)) -> 187553
...

Sheet Workings
B1: Scenario: | L1: Last Updated: | M1: =TODAY() -> 45934 | N1: Back
B3: Workings
H4: 0 | I4: 1 | J4: 2 | K4: 3 | L4: 4 | M4: 5
B5: Revenue
B7: Sales unit | I7: {=INDEX(Assumptions!$E$20:$E$22,Assumptions!$C$1)*(Assumptions!H27*Assumptions!H28)} -> 6000000 | J7: {=INDEX(Assumptions!$E$20:$E$22,Assumptions!$C$1)*(Assumptions!I27*Assumptions!I28)} -> 6082800 | K7: {=INDEX(Assumptions!$E$20:$E$22,Assumptions!$C$1)*(Assumptions!J27*Assumptions!J28)} -> 6082800 | L7: {=INDEX(Assumptions!$E$20:$E$22,Assumptions!$C$1)*(Assumptions!K27*Assumptions!K28)} -> 6082800 | M7: {=INDEX(Assumptions!$E$20:$E$22,Assumptions!$C$1)*(Assumptions!L27*Assumptions!L28)} -> 6082800
B8: Rental unit | I8: {=INDEX(Assumptions!$E$20:$E$22,Assumptions!$C$1)*(Assumptions!H30*Assumptions!H31)} -> 84000 | J8: {=INDEX(Assumptions!$E$20:$E$22,Assumptions!$C$1)*(Assumptions!I30*Assumptions!I31)} -> 170318.4 | K8: {=INDEX(Assumptions!$E$20:$E$22,Assumptions!$C$1)*(Assumptions!J30*Assumptions!J31)} -> 255477.6 | L8: {=INDEX(Assumptions!$E$20:$E$22,Assumptions!$C$1)*(Assumptions!K30*Assumptions!K31)} -> 340636.8 | M8: {=INDEX(Assumptions!$E$20:$E$22,Assumptions!$C$1)*(Assumptions!L30*Assumptions!L31)} -> 425796
I9: =SUM(I7:I8) -> 6084000 | J9: =SUM(J7:J8) -> 6253118.4 | K9: =SUM(K7:K8) -> 6338277.6 | L9: =SUM(L7:L8) -> 6423436.8 | M9: =SUM(M7:M8) -> 6508596
B11: Other income | I11: {=INDEX(Assumptions!$E$20:$E$22,Assumptions!$C$1)*(I9*Assumptions!$E$15)} -> 243360 | J11: {=INDEX(Assumptions!$E$20:$E$22,Assumptions!$C$1)*(J9*Assumptions!$E$15)} -> 250124.74 | K11: {=INDEX(Assumptions!$E$20:$E$22,Assumptions!$C$1)*(K9*Assumptions!$E$15)} -> 253531.1 | L11: {=INDEX(Assumptions!$E$20:$E$22,Assumptions!$C$1)*(L9*Assumptions!$E$15)} -> 256937.47 | M11: {=INDEX(Assumptions!$E$20:$E$22,Assumptions!$C$1)*(M9*Assumptions!$E$15)} -> 260343.84
B13: Total income | I13: =I9+I11 -> 6327360 | J13: =J9+J11 -> 6503243.1 | K13: =K9+K11 -> 6591808.7 | L13: =L9+L11 -> 6680374.3 | M13: =M9+M11 -> 6768939.8
B15: Cost of Sales
B17: Sales unit | I17: {=INDEX(Assumptions!$E$20:$E$22,Assumptions!$C$1)*((Assumptions!H36*Assumptions!H37)+(Assumptions!H36*Assumptions!H37)*Assumptions!H38)} -> 1554000 | J17: {=INDEX(Assumptions!$E$20:$E$22,Assumptions!$C$1)*((Assumptions!I36*Assumptions!I37)+(Assumptions!I36*Assumptions!I37)*Assumptions!I38)} -> 1575445.2 | K17: {=INDEX(Assumptions!$E$20:$E$22,Assumptions!$C$1)*((Assumptions!J36*Assumptions!J37)+(Assumptions!J36*Assumptions!J37)*Assumptions!J38)} -> 1575445.2 | L17: {=INDEX(Assumptions!$E$20:$E$22,Assumptions!$C$1)*((Assumptions!K36*Assumptions!K37)+(Assumptions!K36*Assumptions!K37)*Assumptions!K38)} -> 1575445.2 | M17: {=INDEX(Assumptions!$E$20:$E$22,Assumptions!$C$1)*((Assumptions!L36*Assumptions!L37)+(Assumptions!L36*Assumptions!L37)*Assumptions!L38)} -> 1575445.2
B18: Capitalised interest | I18: =$F101*Assumptions!$E$12 -> 718942.66 | J18: =$F102*Assumptions!$E$12 -> 631341.84 | K18: =$F103*Assumptions!$E$12 -> 521840.81 | L18: =$F104*Assumptions!$E$12 -> 384964.53 | M18: =$F105*Assumptions!$E$12 -> 213869.19
B19: Landed property | I19: =I39 -> 824000 | J19: =J39 -> 824000 | K19: =K39 -> 824000 | L19: =L39 -> 824000 | M19: =M39 -> 824000
I20: =SUM(I17:I19) -> 3096942.7 | J20: =SUM(J17:J19) -> 3030787 | K20: =SUM(K17:K19) -> 2921286 | L20: =SUM(L17:L19) -> 2784409.7 | M20: =SUM(M17:M19) -> 2613314.4
B24: Selling, General & Admin expense
B26: Property management ( % of total income) | I26: =Assumptions!H47*Workings!I13 -> 506188.8 | J26: =Assumptions!I47*Workings!J13 -> 520259.45 | K26: =Assumptions!J47*Workings!K13 -> 527344.7 | L26: =Assumptions!K47*Workings!L13 -> 534429.94 | M26: =Assumptions!L47*Workings!M13 -> 541515.19
B27: Maintenance & repairs ( % of total income) | I27: =I13*Assumptions!H48 -> 94910.4 | J27: =J13*Assumptions!I48 -> 130064.86 | K27: =K13*Assumptions!J48 -> 131836.17 | L27: =L13*Assumptions!K48 -> 133607.49 | M27: =M13*Assumptions!L48 -> 135378.8
B28: Marketing ( % of total income) | I28: =Assumptions!H49*Workings!I13 -> 158184 | J28: =Assumptions!I49*Workings!J13 -> 130064.86 | K28: =Assumptions!J49*Workings!K13 -> 131836.17 | L28: =Assumptions!K49*Workings!L13 -> 100205.61 | M28: =Assumptions!L49*Workings!M13 -> 101534.1
B29: Fuel & Diesel | I29: {=INDEX(Assumptions!$E$20:$E$22,Assumptions!$C$1)*(Assumptions!H50*Assumptions!H6)} -> 60000 | J29: {=INDEX(Assumptions!$E$20:$E$22,Assumptions!$C$1)*(Assumptions!I50*Assumptions!I6)} -> 60000 | K29: {=INDEX(Assumptions!$E$20:$E$22,Assumptions!$C$1)*(Assumptions!J50*Assumptions!J6)} -> 66000 | L29: {=INDEX(Assumptions!$E$20:$E$22,Assumptions!$C$1)*(Assumptions!K50*Assumptions!K6)} -> 72000 | M29: {=INDEX(Assumptions!$E$20:$E$22,Assumptions!$C$1)*(Assumptions!L50*Assumptions!L6)} -> 72000
B30: Legal fee | I30: =Assumptions!H51 -> 30000 | J30: =Assumptions!I51 -> 30000 | K30: =Assumptions!J51 -> 30000 | L30: =Assumptions!K51 -> 30000 | M30: =Assumptions!L51 -> 30000
B31: Other | I31: =Assumptions!H53 -> 15000 | J31: =Assumptions!I53 -> 15000 | K31: =Assumptions!J53 -> 15000 | L31: =Assumptions!K53 -> 15000 | M31: =Assumptions!L53 -> 15000
B32: Pre-operational expenses | I32: {=INDEX(Assumptions!$E$20:$E$22,Assumptions!$C$1)*(SUM(Assumptions!E79,Assumptions!E80,Assumptions!E82,Assumptions!E83))} -> 680000
I33: =SUM(I26:I32) -> 1544283.2 | J33: =SUM(J26:J32) -> 885389.18 | K33: =SUM(K26:K32) -> 902017.04 | L33: =SUM(L26:L32) -> 885243.04 | M33: =SUM(M26:M32) -> 895428.08
B36: Non-current Assets
B38: Landed Property
C39: Sold units | G39: GHS | I39: {=INDEX(Assumptions!$E$20:$E$22,Assumptions!$C$1)*((Assumptions!H36*Assumptions!H39)+(Assumptions!H36*Assumptions!H40))} -> 824000 | J39: {=INDEX(Assumptions!$E$20:$E$22,Assumptions!$C$1)*((Assumptions!I36*Assumptions!I39)+(Assumptions!I36*Assumptions!I40))} -> 824000 | K39: {=INDEX(Assumptions!$E$20:$E$22,Assumptions!$C$1)*((Assumptions!J36*Assumptions!J39)+(Assumptions!J36*Assumptions!J40))} -> 824000 | L39: {=INDEX(Assumptions!$E$20:$E$22,Assumptions!$C$1)*((Assumptions!K36*Assumptions!K39)+(Assumptions!K36*Assumptions!K40))} -> 824000 | M39: {=INDEX(Assumptions!$E$20:$E$22,Assumptions!$C$1)*((Assumptions!L36*Assumptions!L39)+(Assumptions!L36*Assumptions!L40))} -> 824000
C40: Closing Balance | G40: GHS | H40: {=INDEX(Assumptions!$E$20:$E$22,Assumptions!$C$1)*(Assumptions!E77+Assumptions!E78+Assumptions!E81)} -> 5150000 | I40: =H40-I39 -> 4326000 | J40: =I40-J39 -> 3502000 | K40: =J40-K39 -> 2678000 | L40: =K40-L39 -> 1854000 | M40: =L40-M39 -> 1030000
B44: Constructed | F44: USL
C45: Building | F45: 30 | I45: {=INDEX(Assumptions!$E$20:$E$22,Assumptions!$C$1)*((Assumptions!H59*Assumptions!H60)+(Assumptions!H59*Assumptions!H60)*Assumptions!H61)} -> 388500 | J45: {=INDEX(Assumptions!$E$20:$E$22,Assumptions!$C$1)*((Assumptions!I59*Assumptions!I60)+(Assumptions!I59*Assumptions!I59*Assumptions!I61))} -> 375106.2 | K45: {=INDEX(Assumptions!$E$20:$E$22,Assumptions!$C$1)*((Assumptions!J59*Assumptions!J60)+(Assumptions!J59*Assumptions!J59*Assumptions!J61))} -> 375106.2 | L45: {=INDEX(Assumptions!$E$20:$E$22,Assumptions!$C$1)*((Assumptions!K59*Assumptions!K60)+(Assumptions!K59*Assumptions!K59*Assumptions!K61))} -> 375106.2 | M45: {=INDEX(Assumptions!$E$20:$E$22,Assumptions!$C$1)*((Assumptions!L59*Assumptions!L60)+(Assumptions!L59*Assumptions!L59*Assumptions!L61))} -> 375106.2
C46: Capitalised interest | I46: =$F101*Assumptions!$E$13 -> 179735.66 | J46: =$F102*Assumptions!$E$13 -> 157835.46 | K46: =$F103*Assumptions!$E$13 -> 130460.2 | L46: =$F104*Assumptions!$E$13 -> 96241.134 | M46: =$F105*Assumptions!$E$13 -> 53467.297
I47: =SUM(I45:I46) -> 568235.66 | J47: =SUM(J45:J46) -> 532941.66 | K47: =SUM(K45:K46) -> 505566.4 | L47: =SUM(L45:L46) -> 471347.33 | M47: =SUM(M45:M46) -> 428573.5
C49: Land | I49: {=INDEX(Assumptions!$E$20:$E$22,Assumptions!$C$1)*((Assumptions!H59*Assumptions!H39)+(Assumptions!H59*Assumptions!H40))} -> 206000 | J49: {=INDEX(Assumptions!$E$20:$E$22,Assumptions!$C$1)*((Assumptions!I59*Assumptions!I39)+(Assumptions!I59*Assumptions!I40))} -> 206000 | K49: {=INDEX(Assumptions!$E$20:$E$22,Assumptions!$C$1)*((Assumptions!J59*Assumptions!J39)+(Assumptions!J59*Assumptions!J40))} -> 206000 | L49: {=INDEX(Assumptions!$E$20:$E$22,Assumptions!$C$1)*((Assumptions!K59*Assumptions!K39)+(Assumptions!K59*Assumptions!K40))} -> 206000 | M49: {=INDEX(Assumptions!$E$20:$E$22,Assumptions!$C$1)*((Assumptions!L59*Assumptions!L39)+(Assumptions!L59*Assumptions!L40))} -> 206000
C51: Total value | I51: =I47+I49 -> 774235.66 | J51: =J47+J49 -> 738941.66 | K51: =K47+K49 -> 711566.4 | L51: =L47+L49 -> 677347.33 | M51: =M47+M49 -> 634573.5
B53: Acquisition
C54: Furniture & Fittings | F54: 4 | I54: {=INDEX(Assumptions!$E$20:$E$22,Assumptions!$C$1)*(Assumptions!H65*Assumptions!H66)} -> 180000 | J54: {=INDEX(Assumptions!$E$20:$E$22,Assumptions!$C$1)*(Assumptions!I65*Assumptions!I66)} -> 180000 | K54: {=INDEX(Assumptions!$E$20:$E$22,Assumptions!$C$1)*(Assumptions!J65*Assumptions!J66)} -> 175000 | L54: {=INDEX(Assumptions!$E$20:$E$22,Assumptions!$C$1)*(Assumptions!K65*Assumptions!K66)} -> 259000 | M54: {=INDEX(Assumptions!$E$20:$E$22,Assumptions!$C$1)*(Assumptions!L65*Assumptions!L66)} -> 262500
C55: Vehicles | F55: 4 | I55: {=INDEX(Assumptions!$E$20:$E$22,Assumptions!$C$1)*(Assumptions!H70*Assumptions!H71)} -> 170000 | J55: {=INDEX(Assumptions!$E$20:$E$22,Assumptions!$C$1)*(Assumptions!I70*Assumptions!I71)} -> 0 | K55: {=INDEX(Assumptions!$E$20:$E$22,Assumptions!$C$1)*(Assumptions!J70*Assumptions!J71)} -> 90000 | L55: {=INDEX(Assumptions!$E$20:$E$22,Assumptions!$C$1)*(Assumptions!K70*Assumptions!K71)} -> 0 | M55: {=INDEX(Assumptions!$E$20:$E$22,Assumptions!$C$1)*(Assumptions!L70*Assumptions!L71)} -> 90000
I56: =SUM(I54:I55) -> 350000 | J56: =SUM(J54:J55) -> 180000 | K56: =SUM(K54:K55) -> 265000 | L56: =SUM(L54:L55) -> 259000 | M56: =SUM(M54:M55) -> 352500
B60: Depreciation
C61: Building | I61: =SLN(SUM($H47:I47),$G45,$F45) -> 18941.189 | J61: =SLN(SUM($H47:J47),$G45,$F45) -> 36705.911 | K61: =SLN(SUM($H47:K47),$G45,$F45) -> 53558.124 | L61: =SLN(SUM($H47:L47),$G45,$F45) -> 69269.702 | M61: =SLN(SUM($H47:M47),$G45,$F45) -> 83555.485
C64: Furniture & Fittings | I64: =SLN(SUM($H54:I54),$H54,$F54) -> 45000 | J64: =SLN(SUM($H54:J54),$H54,$F54) -> 90000 | K64: =SLN(SUM($H54:K54),$H54,$F54) -> 133750 | L64: =SLN(SUM($H54:L54),$H54,$F54) -> 198500 | M64: =SLN(SUM($H54:M54),$H54,$F54) -> 264125
...

Sheet Income Statement
B1: Scenario: | L1: Last Updated: | M1: =TODAY() -> 45934 | N1: Back
B3: Income Statement
H4: 0 | I4: 1 | J4: 2 | K4: 3 | L4: 4 | M4: 5
B6: Revenue | I6: =Workings!I13 -> 6327360 | J6: =Workings!J13 -> 6503243.1 | K6: =Workings!K13 -> 6591808.7 | L6: =Workings!L13 -> 6680374.3 | M6: =Workings!M13 -> 6768939.8
B7: Cost of Sales | I7: =-Workings!I20 -> -3096942.7 | J7: =-Workings!J20 -> -3030787 | K7: =-Workings!K20 -> -2921286 | L7: =-Workings!L20 -> -2784409.7 | M7: =-Workings!M20 -> -2613314.4
B9: Gross profit | I9: =SUM(I6:I8) -> 3230417.3 | J9: =SUM(J6:J8) -> 3472456.1 | K9: =SUM(K6:K8) -> 3670522.7 | L9: =SUM(L6:L8) -> 3895964.5 | M9: =SUM(M6:M8) -> 4155625.5
B11: SG&A | I11: =-Workings!I33 -> -1544283.2 | J11: =-Workings!J33 -> -885389.18 | K11: =-Workings!K33 -> -902017.04 | L11: =-Workings!L33 -> -885243.04 | M11: =-Workings!M33 -> -895428.08
B13: Operating Profit (EBITA) | I13: =SUM(I9:I12) -> 1686134.1 | J13: =SUM(J9:J12) -> 2587066.9 | K13: =SUM(K9:K12) -> 2768505.6 | L13: =SUM(L9:L12) -> 3010721.5 | M13: =SUM(M9:M12) -> 3260197.4
B15: Depreciation | I15: =-Workings!I66 -> -106441.19 | J15: =-Workings!J66 -> -169205.91 | K15: =-Workings!K66 -> -252308.12 | L15: =-Workings!L66 -> -332769.7 | M15: =-Workings!M66 -> -435180.49
B17: Profit /Loss Before Tax (EBT) | I17: =SUM(I13:I16) -> 1579693 | J17: =IF(SUM(J13:J16)<0,"",SUM(J13:J16)) -> 2417861 | K17: =IF(SUM(K13:K16)<0,"",SUM(K13:K16)) -> 2516197.5 | L17: =IF(SUM(L13:L16)<0,"",SUM(L13:L16)) -> 2677951.8 | M17: =IF(SUM(M13:M16)<0,"",SUM(M13:M16)) -> 2825016.9
B19: Tax expense | I19: =IF(SUM(I13:I16)<0,"",-I17*Assumptions!$E$16) -> -394923.24 | J19: =-J17*Assumptions!$E$16 -> -604465.25 | K19: =-K17*Assumptions!$E$16 -> -629049.38 | L19: =-L17*Assumptions!$E$16 -> -669487.95 | M19: =-M17*Assumptions!$E$16 -> -706254.22
B21: Profit/Loss After Tax | I21: =SUM(I17:I20) -> 1184769.7 | J21: =SUM(J17:J20) -> 1813395.8 | K21: =SUM(K17:K20) -> 1887148.1 | L21: =SUM(L17:L20) -> 2008463.8 | M21: =SUM(M17:M20) -> 2118762.7
B23: Dividend | I23: =IF(I21<0,0,-I21*Assumptions!$E$94) -> -236953.94 | J23: =IF(J21<0,0,-J21*Assumptions!$E$94) -> -362679.15 | K23: =IF(K21<0,0,-K21*Assumptions!$E$94) -> -377429.63 | L23: =IF(L21<0,0,-L21*Assumptions!$E$94) -> -401692.77 | M23: =IF(M21<0,0,-M21*Assumptions!$E$94) -> -423752.53
B25: Retained Earnings | I25: =IF(SUM(I21:I24)<0,0,SUM(I21:I24)) -> 947815.77 | J25: =IF(SUM(J21:J24)<0,0,SUM(J21:J24)) -> 1450716.6 | K25: =IF(SUM(K21:K24)<0,0,SUM(K21:K24)) -> 1509718.5 | L25: =IF(SUM(L21:L24)<0,0,SUM(L21:L24)) -> 1606771.1 | M25: =IF(SUM(M21:M24)<0,0,SUM(M21:M24)) -> 1695010.1
B26: Commulative Retained Earnings | I26: =H26+I25 -> 947815.77 | J26: =I26+J25 -> 2398532.4 | K26: =J26+K25 -> 3908250.9 | L26: =K26+L25 -> 5515022 | M26: =L26+M25 -> 7210032.1

Sheet Balance Sheet
B1: Scenario: | L1: Last Updated: | M1: =TODAY() -> 45934 | N1: Back
B3: Balance Sheet
H4: 0 | I4: 1 | J4: 2 | K4: 3 | L4: 4 | M4: 5
B5: Assets
C6: Non-current Assets
C7: Property, Plant & Equipment
D8: Building | I8: =SUM(Workings!$H47:I47) -> 568235.66 | J8: =SUM(Workings!$H47:J47) -> 1101177.3 | K8: =SUM(Workings!$H47:K47) -> 1606743.7 | L8: =SUM(Workings!$H47:L47) -> 2078091.1 | M8: =SUM(Workings!$H47:M47) -> 2506664.6
D9: Landed property | I9: =Workings!I40 -> 4326000 | J9: =Workings!J40 -> 3502000 | K9: =Workings!K40 -> 2678000 | L9: =Workings!L40 -> 1854000 | M9: =Workings!M40 -> 1030000
D10: Furniture & Fittings | I10: =SUM(Workings!$H54:I54) -> 180000 | J10: =SUM(Workings!$H54:J54) -> 360000 | K10: =SUM(Workings!$H54:K54) -> 535000 | L10: =SUM(Workings!$H54:L54) -> 794000 | M10: =SUM(Workings!$H54:M54) -> 1056500
D11: Vehicle | I11: =SUM(Workings!$H55:I55) -> 170000 | J11: =SUM(Workings!$H55:J55) -> 170000 | K11: =SUM(Workings!$H55:K55) -> 260000 | L11: =SUM(Workings!$H55:L55) -> 260000 | M11: =SUM(Workings!$H55:M55) -> 350000
D12: Accumulated Depreciation | I12: =-Workings!I72 -> -106441.19 | J12: =-Workings!J72 -> -275647.1 | K12: =-Workings!K72 -> -527955.22 | L12: =-Workings!L72 -> -860724.93 | M12: =-Workings!M72 -> -1295905.4
D13: Net Book Value | I13: =SUM(I8:I12) -> 5137794.5 | J13: =SUM(J8:J12) -> 4857530.2 | K13: =SUM(K8:K12) -> 4551788.5 | L13: =SUM(L8:L12) -> 4125366.1 | M13: =SUM(M8:M12) -> 3647259.1
C15: Current Assets
D16: Cash & Cash Equivalent | I16: ='Cashflow Statement'!I35 -> 5184927.6 | J16: ='Cashflow Statement'!J35 -> 6704475.7 | K16: ='Cashflow Statement'!K35 -> 7874889.1 | L16: ='Cashflow Statement'!L35 -> 9117307.5 | M16: ='Cashflow Statement'!M35 -> 10279905
C17: Total Current Assets | I17: =SUM(I16:I16) -> 5184927.6 | J17: =SUM(J16:J16) -> 6704475.7 | K17: =SUM(K16:K16) -> 7874889.1 | L17: =SUM(L16:L16) -> 9117307.5 | M17: =SUM(M16:M16) -> 10279905
C19: Current Liabilities
D20: Retention(Held till Defect) | I20: =Workings!I109 -> 194250 | J20: =Workings!J109 -> 195055.14 | K20: =Workings!K109 -> 195055.14 | L20: =Workings!L109 -> 195055.14 | M20: =Workings!M109 -> 195055.14
D21: Dividend Payable | I21: =-'Income Statement'!I23 -> 236953.94 | J21: =-'Income Statement'!J23 -> 362679.15 | K21: =-'Income Statement'!K23 -> 377429.63 | L21: =-'Income Statement'!L23 -> 401692.77 | M21: =-'Income Statement'!M23 -> 423752.53
D22: Tax payable | I22: =-'Income Statement'!I19 -> 394923.24 | J22: =-'Income Statement'!J19 -> 604465.25 | K22: =-'Income Statement'!K19 -> 629049.38 | L22: =-'Income Statement'!L19 -> 669487.95 | M22: =-'Income Statement'!M19 -> 706254.22
D23: Loan payable | L23: =Workings!H104 -> 1069345.9
I24: =SUM(I20:I23) -> 826127.18 | J24: =SUM(J20:J23) -> 1162199.5 | K24: =SUM(K20:K23) -> 1201534.1 | L24: =SUM(L20:L23) -> 2335581.8 | M24: =SUM(M20:M23) -> 1325061.9
C26: Net Current Assets | I26: =I17-I24 -> 4358800.4 | J26: =J17-J24 -> 5542276.1 | K26: =K17-K24 -> 6673355 | L26: =L17-L24 -> 6781725.8 | M26: =M17-M24 -> 8954842.9
C28: Capital Employed | I28: =I26+I13 -> 9496594.9 | J28: =J26+J13 -> 10399806 | K28: =K26+K13 -> 11225143 | L28: =L26+L13 -> 10907092 | M28: =M26+M13 -> 12602102
B30: Equity & Liabilities
D31: Shareholders Equity | I31: =Workings!$I$87 -> 5392069.9 | J31: =Workings!$I$87 -> 5392069.9 | K31: =Workings!$I$87 -> 5392069.9 | L31: =Workings!$I$87 -> 5392069.9 | M31: =Workings!$I$87 -> 5392069.9
D32: Cummulative Retained Earnings | I32: ='Income Statement'!I26 -> 947815.77 | J32: ='Income Statement'!J26 -> 2398532.4 | K32: ='Income Statement'!K26 -> 3908250.9 | L32: ='Income Statement'!L26 -> 5515022 | M32: ='Income Statement'!M26 -> 7210032.1
C33: Total Equity | I33: =SUM(I31:I32) -> 6339885.7 | J33: =SUM(J31:J32) -> 7790602.3 | K33: =SUM(K31:K32) -> 9300320.8 | L33: =SUM(L31:L32) -> 10907092 | M33: =SUM(M31:M32) -> 12602102
C35: Non-current Liabilities
D36: Loan payable | I36: =Workings!H101 -> 3156709.2 | J36: =Workings!H102 -> 2609204.1 | K36: =Workings!H103 -> 1924822.7
C38: Total Non-current Assets | I38: =SUM(I36:I37) -> 3156709.2 | J38: =SUM(J36:J37) -> 2609204.1 | K38: =SUM(K36:K37) -> 1924822.7 | L38: =SUM(L36:L37) -> 0 | M38: =SUM(M36:M37) -> 0
C40: Capital Employed | I40: =I33+I36 -> 9496594.9 | J40: =J33+J36 -> 10399806 | K40: =K33+K36 -> 11225143 | L40: =L33+L36 -> 10907092 | M40: =M33+M36 -> 12602102
C42: Check | I42: =I28=I40 -> TRUE | J42: =J28=J40 -> TRUE | K42: =K28=K40 -> TRUE | L42: =L28=L40 -> TRUE | M42: =M28=M40 -> TRUE
I43: =I40-I28 -> 0 | J43: =J40-J28 -> 0 | K43: =K40-K28 -> 0 | L43: =L40-L28 -> 0 | M43: =M40-M28 -> 0

Sheet Cashflow Statement
B1: Scenario: | L1: Last Updated: | M1: =TODAY() -> 45934 | N1: Back
B3: Cashflow Statement
H4: 0 | I4: 1 | J4: 2 | K4: 3 | L4: 4 | M4: 5
B5: Operating Activities:
C6: Pofit/Loss After Tax | I6: ='Income Statement'!I21 -> 1184769.7 | J6: ='Income Statement'!J21 -> 1813395.8 | K6: ='Income Statement'!K21 -> 1887148.1 | L6: ='Income Statement'!L21 -> 2008463.8 | M6: ='Income Statement'!M21 -> 2118762.7
C7: Adjustments:
D8: Cost of sales(Landed property) | J8: =Workings!J19 -> 824000 | K8: =Workings!K19 -> 824000 | L8: =Workings!L19 -> 824000 | M8: =Workings!M19 -> 824000
D9: Depreciation | I9: =-'Income Statement'!I15 -> 106441.19 | J9: =-'Income Statement'!J15 -> 169205.91 | K9: =-'Income Statement'!K15 -> 252308.12 | L9: =-'Income Statement'!L15 -> 332769.7 | M9: =-'Income Statement'!M15 -> 435180.49
D10: Tax Expense | I10: =IFERROR(-'Income Statement'!I19,"") -> 394923.24 | J10: =IFERROR(-'Income Statement'!J19,"") -> 604465.25 | K10: =IFERROR(-'Income Statement'!K19,"") -> 629049.38 | L10: =IFERROR(-'Income Statement'!L19,"") -> 669487.95 | M10: =IFERROR(-'Income Statement'!M19,"") -> 706254.22
D11: Interest expense | I11: =Workings!I18 -> 718942.66 | J11: =Workings!J18 -> 631341.84 | K11: =Workings!K18 -> 521840.81 | L11: =Workings!L18 -> 384964.53 | M11: =Workings!M18 -> 213869.19
I12: =SUM(I6:I11) -> 2405076.8 | J12: =SUM(J6:J11) -> 4042408.8 | K12: =SUM(K6:K11) -> 4114346.5 | L12: =SUM(L6:L11) -> 4219686 | M12: =SUM(M6:M11) -> 4298066.6
B13: Working Capital Adjustment:
C14: Retention(Held till Defect) | I14: =-'Balance Sheet'!H20 -> 0 | J14: =-'Balance Sheet'!I20 -> -194250 | K14: =-'Balance Sheet'!J20 -> -195055.14 | L14: =-'Balance Sheet'!K20 -> -195055.14 | M14: =-'Balance Sheet'!L20 -> -195055.14
I15: =SUM(I14:I14) -> 0 | J15: =SUM(J14:J14) -> -194250 | K15: =SUM(K14:K14) -> -195055.14 | L15: =SUM(L14:L14) -> -195055.14 | M15: =SUM(M14:M14) -> -195055.14
C16: Taxation | I16: ='Income Statement'!H19 -> 0 | J16: ='Income Statement'!I19 -> -394923.24 | K16: ='Income Statement'!J19 -> -604465.25 | L16: ='Income Statement'!K19 -> -629049.38 | M16: ='Income Statement'!L19 -> -669487.95
B18: Net Cashflow from Operating Activities | I18: =I12+I15+I16 -> 2405076.8 | J18: =J12+J15+J16 -> 3453235.5 | K18: =K12+K15+K16 -> 3314826.1 | L18: =L12+L15+L16 -> 3395581.5 | M18: =M12+M15+M16 -> 3433523.5
B20: Investing Activities:
C21: PPE | I21: =-(Workings!I40+Workings!I45+Workings!I54+Workings!I55) -> -5064500 | J21: =-(Workings!J45+Workings!J54+Workings!J55) -> -555106.2 | K21: =-(Workings!K45+Workings!K54+Workings!K55) -> -640106.2 | L21: =-(Workings!L45+Workings!L54+Workings!L55) -> -634106.2 | M21: =-(Workings!M45+Workings!M54+Workings!M55) -> -727606.2
C22: Rentention(Held till defect) | I22: =Workings!I109 -> 194250 | J22: =Workings!J109 -> 195055.14 | K22: =Workings!K109 -> 195055.14 | L22: =Workings!L109 -> 195055.14 | M22: =Workings!M109 -> 195055.14
B23: Net Cashflow Investing Activities | I23: =SUM(I21:I22) -> -4870250 | J23: =SUM(J21:J22) -> -360051.06 | K23: =SUM(K21:K22) -> -445051.06 | L23: =SUM(L21:L22) -> -439051.06 | M23: =SUM(M21:M22) -> -532551.06
B25: Financing Activities:
C26: Shareholders Equity | I26: =Workings!I87 -> 5392069.9
C27: Proceeds from debt issue | I27: =Workings!I88 -> 3594713.3
C28: Dividend payment | I28: ='Income Statement'!H23 -> 0 | J28: ='Income Statement'!I23 -> -236953.94 | K28: ='Income Statement'!J23 -> -362679.15 | L28: ='Income Statement'!K23 -> -377429.63 | M28: ='Income Statement'!L23 -> -401692.77
C29: Loan repayment | I29: =-Workings!$E101 -> -1336682.4 | J29: =-Workings!$E101 -> -1336682.4 | K29: =-Workings!$E101 -> -1336682.4 | L29: =-Workings!$E101 -> -1336682.4 | M29: =-Workings!$E101 -> -1336682.4
B31: Net Cashflow from Financing Activities | I31: =SUM(I26:I30) -> 7650100.8 | J31: =SUM(J26:J30) -> -1573636.4 | K31: =SUM(K26:K30) -> -1699361.6 | L31: =SUM(L26:L30) -> -1714112 | M31: =SUM(M26:M30) -> -1738375.2
B33: Net Changes in Cash & Cash Equivalent | I33: =I18+I23+I31 -> 5184927.6 | J33: =J18+J23+J31 -> 1519548.1 | K33: =K18+K23+K31 -> 1170413.4 | L33: =L18+L23+L31 -> 1242418.4 | M33: =M18+M23+M31 -> 1162597.2
B34: Opening Balance | I34: 0 | J34: =I35 -> 5184927.6 | K34: =J35 -> 6704475.7 | L34: =K35 -> 7874889.1 | M34: =L35 -> 9117307.5
B35: Closing Balance | I35: =SUM(I33:I34) -> 5184927.6 | J35: =SUM(J33:J34) -> 6704475.7 | K35: =SUM(K33:K34) -> 7874889.1 | L35: =SUM(L33:L34) -> 9117307.5 | M35: =SUM(M33:M34) -> 10279905

Sheet Valuation
B1: Scenario: | L1: Last Updated: | M1: =TODAY() -> 45934 | N1: Back
B3: Valuation
H4: 0 | I4: 1 | J4: 2 | K4: 3 | L4: 4 | M4: 5
B5: Free Cashflow to Firm
B6: (Unlevered free cashflow)
C7: Net income | I7: ='Income Statement'!I21 -> 1184769.7 | J7: ='Income Statement'!J21 -> 1813395.8 | K7: ='Income Statement'!K21 -> 1887148.1 | L7: ='Income Statement'!L21 -> 2008463.8 | M7: ='Income Statement'!M21 -> 2118762.7
C9: Add non-cash items:
D10: Depreciation | I10: =-'Income Statement'!I15 -> 106441.19 | J10: =-'Income Statement'!J15 -> 169205.91 | K10: =-'Income Statement'!K15 -> 252308.12 | L10: =-'Income Statement'!L15 -> 332769.7 | M10: =-'Income Statement'!M15 -> 435180.49
D11: Cost of sales(Landed property) | J11: =Workings!J39 -> 824000 | K11: =Workings!K39 -> 824000 | L11: =Workings!L39 -> 824000 | M11: =Workings!M39 -> 824000
C12: Add :
D13: Tax Savings | I13: =Workings!I116 -> 674008.74 | J13: =Workings!J116 -> 591882.97 | K13: =Workings!K116 -> 489225.76 | L13: =Workings!L116 -> 360904.25 | M13: =Workings!M116 -> 200502.36
C14: Less:
D15: CapEx | I15: ='Cashflow Statement'!I21 -> -5064500 | J15: ='Cashflow Statement'!J21 -> -555106.2 | K15: ='Cashflow Statement'!K21 -> -640106.2 | L15: ='Cashflow Statement'!L21 -> -634106.2 | M15: ='Cashflow Statement'!M21 -> -727606.2
B17: FCFF | I17: =SUM(I7:I16) -> -3099280.4 | J17: =SUM(J7:J16) -> 2843378.4 | K17: =SUM(K7:K16) -> 2812575.8 | L17: =SUM(L7:L16) -> 2892031.6 | M17: =SUM(M7:M16) -> 2850839.3
B18: Terminal Value | F18: YR5 FCFF*(1+G) | M18: =(M17*(1+C57))/(C53-C57) -> 24446689
F19: WACC - G
F21: Total FCFF | I21: =SUM(I17:I18) -> -3099280.4 | J21: =SUM(J17:J18) -> 2843378.4 | K21: =SUM(K17:K18) -> 2812575.8 | L21: =SUM(L17:L18) -> 2892031.6 | M21: =SUM(M17:M18) -> 27297529
B23: Discount Factor | F23: (1+WACC)^-n | I23: =(1+Workings!$H$121)^-Valuation!I4 -> 0.86194822 | J23: =(1+Workings!$H$121)^-Valuation!J4 -> 0.74295473 | K23: =(1+Workings!$H$121)^-Valuation!K4 -> 0.6403885 | L23: =(1+Workings!$H$121)^-Valuation!L4 -> 0.55198173 | M23: =(1+Workings!$H$121)^-Valuation!M4 -> 0.47577967
F25: Present Value | I25: =I21*I23 -> -2671419.2 | J25: =J21*J23 -> 2112501.5 | K25: =K21*K23 -> 1801141.2 | L25: =L21*L23 -> 1596348.6 | M25: =M21*M23 -> 12987609
F27: Enterprise Value | I27: =SUM(I25:M25) -> 15826181
B30: Free Cashflow to Equity
B31: (Levered free cashflow)
C32: Net income | I32: ='Income Statement'!I21 -> 1184769.7 | J32: ='Income Statement'!J21 -> 1813395.8 | K32: ='Income Statement'!K21 -> 1887148.1 | L32: ='Income Statement'!L21 -> 2008463.8 | M32: ='Income Statement'!M21 -> 2118762.7
C34: Add non-cash items:
D35: Depreciation | I35: =-'Income Statement'!I15 -> 106441.19 | J35: =-'Income Statement'!J15 -> 169205.91 | K35: =-'Income Statement'!K15 -> 252308.12 | L35: =-'Income Statement'!L15 -> 332769.7 | M35: =-'Income Statement'!M15 -> 435180.49
D36: Cost of sales(Landed property) | J36: =Workings!J39 -> 824000 | K36: =Workings!K39 -> 824000 | L36: =Workings!L39 -> 824000 | M36: =Workings!M39 -> 824000
C37: Less:
D38: CapEx | I38: ='Cashflow Statement'!I21 -> -5064500 | J38: ='Cashflow Statement'!J21 -> -555106.2 | K38: ='Cashflow Statement'!K21 -> -640106.2 | L38: ='Cashflow Statement'!L21 -> -634106.2 | M38: ='Cashflow Statement'!M21 -> -727606.2
D40: Net Debt | F40: (End Bal - Open Bal) | I40: ='Balance Sheet'!I36-'Balance Sheet'!H36 -> 3156709.2 | J40: ='Balance Sheet'!J36-'Balance Sheet'!I36 -> -547505.12 | K40: ='Balance Sheet'!K36-'Balance Sheet'!J36 -> -684381.4 | L40: ='Balance Sheet'!L36-'Balance Sheet'!K36 -> -1924822.7
B41: FCFF | I41: =SUM(I32:I40) -> -616579.91 | J41: =SUM(J32:J40) -> 1703990.4 | K41: =SUM(K32:K40) -> 1638968.7 | L41: =SUM(L32:L40) -> 606304.67 | M41: =SUM(M32:M40) -> 2650337
B42: Terminal Value | F42: YR5 FCFF*(1+G) | M42: =(M41*(1+C57))/(C55-C57) -> 26751184
F43: Ke - G
F45: Total FCFE | I45: =SUM(I41:I42) -> -616579.91 | J45: =SUM(J41:J42) -> 1703990.4 | K45: =SUM(K41:K42) -> 1638968.7 | L45: =SUM(L41:L42) -> 606304.67 | M45: =SUM(M41:M42) -> 29401521
B47: Discount Factor | F47: (1+Ke)^-n | I47: =(1+Workings!$H$126)^-Valuation!I4 -> 0.8 | J47: =(1+Workings!$H$126)^-Valuation!J4 -> 0.64 | K47: =(1+Workings!$H$126)^-Valuation!K4 -> 0.512 | L47: =(1+Workings!$H$126)^-Valuation!L4 -> 0.4096 | M47: =(1+Workings!$H$126)^-Valuation!M4 -> 0.32768
F49: Present Value | I49: =I45*I47 -> -493263.93 | J49: =J45*J47 -> 1090553.8 | K49: =K45*K47 -> 839151.96 | L49: =L45*L47 -> 248342.39 | M49: =M45*M47 -> 9634290.5
F51: Enterprise Value | I51: =SUM(I49:M49) -> 11319075
B53: WACC | C53: =Workings!H121 -> 0.1601625
B55: Cost of Equity | C55: =Workings!H123 -> 0.1419375
B57: Growth rate | C57: =Assumptions!E100 -> 0.039

Sheet Financial Ratios
B1: Scenario: | I1: Last Updated: | J1: =TODAY() -> 45934 | K1: Back
B3: Financial Ratios
E4: 0 | F4: 1 | G4: 2 | H4: 3 | I4: 4 | J4: 5
B6: Profitability
C7: GP Margin | F7: ='Income Statement'!I9/'Income Statement'!I6 -> 0.51054742 | G7: ='Income Statement'!J9/'Income Statement'!J6 -> 0.5339576 | H7: ='Income Statement'!K9/'Income Statement'!K6 -> 0.55683089 | I7: ='Income Statement'!L9/'Income Statement'!L6 -> 0.58319555 | J7: ='Income Statement'!M9/'Income Statement'!M6 -> 0.6139256
C8: OP Margin | F8: ='Income Statement'!I13/'Income Statement'!I6 -> 0.26648304 | G8: ='Income Statement'!J13/'Income Statement'!J6 -> 0.39781181 | H8: ='Income Statement'!K13/'Income Statement'!K6 -> 0.41999181 | I8: ='Income Statement'!L13/'Income Statement'!L6 -> 0.45068156 | J8: ='Income Statement'!M13/'Income Statement'!M6 -> 0.48164077
C9: NP Margin | F9: ='Income Statement'!I21/'Income Statement'!I6 -> 0.1872455 | G9: ='Income Statement'!J21/'Income Statement'!J6 -> 0.27884483 | H9: ='Income Statement'!K21/'Income Statement'!K6 -> 0.28628685 | I9: ='Income Statement'!L21/'Income Statement'!L6 -> 0.3006514 | J9: ='Income Statement'!M21/'Income Statement'!M6 -> 0.31301248
C11: ROCE | F11: ='Income Statement'!I13/('Balance Sheet'!I28) -> 0.17755145 | G11: ='Income Statement'!J13/('Balance Sheet'!J28) -> 0.24876107 | H11: ='Income Statement'!K13/('Balance Sheet'!K28) -> 0.24663432 | I11: ='Income Statement'!L13/('Balance Sheet'!L28) -> 0.27603339 | J11: ='Income Statement'!M13/('Balance Sheet'!M28) -> 0.25870266
C12: ROA | F12: ='Income Statement'!I21/('Balance Sheet'!I13+'Balance Sheet'!I17) -> 0.11477299 | G12: ='Income Statement'!J21/('Balance Sheet'!J13+'Balance Sheet'!J17) -> 0.15684093 | H12: ='Income Statement'!K21/('Balance Sheet'!K13+'Balance Sheet'!K17) -> 0.15186265 | I12: ='Income Statement'!L21/('Balance Sheet'!L13+'Balance Sheet'!L17) -> 0.15166604 | J12: ='Income Statement'!M21/('Balance Sheet'!M13+'Balance Sheet'!M17) -> 0.15213167
B15: Liquidity
C16: Current Ratio | F16: ='Balance Sheet'!I17/'Balance Sheet'!I24 -> 6.2761857 | G16: ='Balance Sheet'!J17/'Balance Sheet'!J24 -> 5.7687819 | H16: ='Balance Sheet'!K17/'Balance Sheet'!K24 -> 6.5540286 | I16: ='Balance Sheet'!L17/'Balance Sheet'!L24 -> 3.9036559 | J16: ='Balance Sheet'!M17/'Balance Sheet'!M24 -> 7.7580563
C17: Quick (Acid Test) Ratio | F17: ='Balance Sheet'!I17/'Balance Sheet'!I24 -> 6.2761857 | G17: ='Balance Sheet'!J17/'Balance Sheet'!J24 -> 5.7687819 | H17: ='Balance Sheet'!K17/'Balance Sheet'!K24 -> 6.5540286 | I17: ='Balance Sheet'!L17/'Balance Sheet'!L24 -> 3.9036559 | J17: ='Balance Sheet'!M17/'Balance Sheet'!M24 -> 7.7580563
C18: Cash Ratio | F18: ='Balance Sheet'!I16/'Balance Sheet'!I24 -> 6.2761857 | G18: ='Balance Sheet'!J16/'Balance Sheet'!J24 -> 5.7687819 | H18: ='Balance Sheet'!K16/'Balance Sheet'!K24 -> 6.5540286 | I18: ='Balance Sheet'!L16/'Balance Sheet'!L24 -> 3.9036559 | J18: ='Balance Sheet'!M16/'Balance Sheet'!M24 -> 7.7580563
B21: Leverage
C22: Debt to Equity | F22: =('Balance Sheet'!I36+'Balance Sheet'!I23)/'Balance Sheet'!I33 -> 0.49791263 | G22: =('Balance Sheet'!J36+'Balance Sheet'!J23)/'Balance Sheet'!J33 -> 0.33491686 | H22: =('Balance Sheet'!K36+'Balance Sheet'!K23)/'Balance Sheet'!K33 -> 0.20696304 | I22: =('Balance Sheet'!L36+'Balance Sheet'!L23)/'Balance Sheet'!L33 -> 0.098041342 | J22: =('Balance Sheet'!M36+'Balance Sheet'!M23)/'Balance Sheet'!M33 -> 0
C23: Equity Ratio | F23: ='Balance Sheet'!I33/('Balance Sheet'!I13+'Balance Sheet'!I17) -> 0.61416801 | G23: ='Balance Sheet'!J33/('Balance Sheet'!J13+'Balance Sheet'!J17) -> 0.67381061 | H23: ='Balance Sheet'!K33/('Balance Sheet'!K13+'Balance Sheet'!K17) -> 0.74841571 | I23: ='Balance Sheet'!L33/('Balance Sheet'!L13+'Balance Sheet'!L17) -> 0.82363216 | J23: ='Balance Sheet'!M33/('Balance Sheet'!M13+'Balance Sheet'!M17) -> 0.90485774
C24: Debt Ratio | F24: =('Balance Sheet'!I36+'Balance Sheet'!I23)/('Balance Sheet'!I13+'Balance Sheet'!I17) -> 0.30580201 | G24: =('Balance Sheet'!J36+'Balance Sheet'!J23)/('Balance Sheet'!J13+'Balance Sheet'!J17) -> 0.22567054 | H24: =('Balance Sheet'!K36+'Balance Sheet'!K23)/('Balance Sheet'!K13+'Balance Sheet'!K17) -> 0.15489439 | I24: =('Balance Sheet'!L36+'Balance Sheet'!L23)/('Balance Sheet'!L13+'Balance Sheet'!L17) -> 0.080750002 | J24: =('Balance Sheet'!M36+'Balance Sheet'!M23)/('Balance Sheet'!M13+'Balance Sheet'!M17) -> 0
C25: Interest Coverage | F25: ='Income Statement'!I13/Workings!$F101 -> 1.8762377 | G25: ='Income Statement'!J13/Workings!$F102 -> 3.2781821 | H25: ='Income Statement'!K13/Workings!$F103 -> 4.2442148 | I25: ='Income Statement'!L13/Workings!$F104 -> 6.256621 | J25: ='Income Statement'!M13/Workings!$F105 -> 12.195108
B28: Efficiency
C30: Working Capital | F30: ='Balance Sheet'!I17-'Balance Sheet'!I24 -> 4358800.4 | G30: ='Balance Sheet'!J17-'Balance Sheet'!J24 -> 5542276.1 | H30: ='Balance Sheet'!K17-'Balance Sheet'!K24 -> 6673355 | I30: ='Balance Sheet'!L17-'Balance Sheet'!L24 -> 6781725.8 | J30: ='Balance Sheet'!M17-'Balance Sheet'!M24 -> 8954842.9

Sheet Data Page
K1: Last Updated: | L1: =TODAY() -> 45934 | M1: Back
B3: Dataset
B5: Year | C5: Revenue | D5: COS | E5: Gross Profit | F5: Opex Items | G5: OPEX | H5: Operating Profit | I5: Net Profit | J5: GP Margin | K5: NP Margin | L5: ROCE
B6: 2026 | C6: ='Income Statement'!I6 -> 6327360 | D6: =-'Income Statement'!I7 -> 3096942.7 | E6: ='Income Statement'!I9 -> 3230417.3 | H6: ='Income Statement'!I13 -> 1686134.1 | I6: ='Income Statement'!I21 -> 1184769.7 | J6: ='Financial Ratios'!F7 -> 0.51054742 | K6: ='Financial Ratios'!F9 -> 0.1872455 | L6: ='Financial Ratios'!F11 -> 0.17755145
B7: 2027 | C7: ='Income Statement'!J6 -> 6503243.1 | D7: =-'Income Statement'!J7 -> 3030787 | E7: ='Income Statement'!J9 -> 3472456.1 | H7: ='Income Statement'!J13 -> 2587066.9 | I7: ='Income Statement'!J21 -> 1813395.8 | J7: ='Financial Ratios'!G7 -> 0.5339576 | K7: ='Financial Ratios'!G9 -> 0.27884483 | L7: ='Financial Ratios'!G11 -> 0.24876107
B8: 2028 | C8: ='Income Statement'!K6 -> 6591808.7 | D8: =-'Income Statement'!K7 -> 2921286 | E8: ='Income Statement'!K9 -> 3670522.7 | H8: ='Income Statement'!K13 -> 2768505.6 | I8: ='Income Statement'!K21 -> 1887148.1 | J8: ='Financial Ratios'!H7 -> 0.55683089 | K8: ='Financial Ratios'!H9 -> 0.28628685 | L8: ='Financial Ratios'!H11 -> 0.24663432
B9: 2029 | C9: ='Income Statement'!L6 -> 6680374.3 | D9: =-'Income Statement'!L7 -> 2784409.7 | E9: ='Income Statement'!L9 -> 3895964.5 | H9: ='Income Statement'!L13 -> 3010721.5 | I9: ='Income Statement'!L21 -> 2008463.8 | J9: ='Financial Ratios'!I7 -> 0.58319555 | K9: ='Financial Ratios'!I9 -> 0.3006514 | L9: ='Financial Ratios'!I11 -> 0.27603339
B10: 2030 | C10: ='Income Statement'!M6 -> 6768939.8 | D10: =-'Income Statement'!M7 -> 2613314.4 | E10: ='Income Statement'!M9 -> 4155625.5 | H10: ='Income Statement'!M13 -> 3260197.4 | I10: ='Income Statement'!M21 -> 2118762.7 | J10: ='Financial Ratios'!J7 -> 0.6139256 | K10: ='Financial Ratios'!J9 -> 0.31301248 | L10: ='Financial Ratios'!J11 -> 0.25870266
B11: 2026 | F11: Other Expenses | G11: =-'Income Statement'!I11 -> 1544283.2
B12: 2026 | F12: Depreciation | G12: =-'Income Statement'!I15 -> 106441.19
B13: 2027 | F13: Other Expenses | G13: =-'Income Statement'!J11 -> 885389.18
B14: 2027 | F14: Depreciation | G14: =-'Income Statement'!J15 -> 169205.91
B15: 2028 | F15: Other Expenses | G15: =-'Income Statement'!K11 -> 902017.04
B16: 2028 | F16: Depreciation | G16: =-'Income Statement'!K15 -> 252308.12
B17: 2029 | F17: Other Expenses | G17: =-'Income Statement'!L11 -> 885243.04
B18: 2029 | F18: Depreciation | G18: =-'Income Statement'!L15 -> 332769.7
B19: 2030 | F19: Other Expenses | G19: =-'Income Statement'!M11 -> 895428.08
B20: 2030 | F20: Depreciation | G20: =-'Income Statement'!M15 -> 435180.49

Sheet Pivot Tables
B3: Row Labels | C3: Sum of Revenue | D3: Sum of COS | E3: Sum of Gross Profit | F3: Sum of Net Profit
B4: 2026 | C4: 6327360 | D4: 3096942.7 | E4: 3230417.3 | F4: 1184769.7
B5: 2027 | C5: 6503243.1 | D5: 3030787 | E5: 3472456.1 | F5: 1813395.8
B6: 2028 | C6: 6591808.7 | D6: 2921286 | E6: 3670522.7 | F6: 1887148.1
B7: 2029 | C7: 6680374.3 | D7: 2784409.7 | E7: 3895964.5 | F7: 2008463.8
B8: 2030 | C8: 6768939.8 | D8: 2613314.4 | E8: 4155625.5 | F8: 2118762.7
B9: Grand Total | C9: 32871726 | D9: 14446740 | E9: 18424986 | F9: 9012540.1
B11: Row Labels | C11: Average of Revenue | D11: Average of Gross Profit | E11: Average of Net Profit
B12: 2026 | C12: 6327360 | D12: 3230417.3 | E12: 1184769.7
B13: 2027 | C13: 6503243.1 | D13: 3472456.1 | E13: 1813395.8
B14: 2028 | C14: 6591808.7 | D14: 3670522.7 | E14: 1887148.1
B15: 2029 | C15: 6680374.3 | D15: 3895964.5 | E15: 2008463.8
B16: 2030 | C16: 6768939.8 | D16: 4155625.5 | E16: 2118762.7 | H16: Revenue | I16: Gross Profit | J16: Net Profit
B17: Grand Total | C17: 6574345.2 | D17: 3684997.2 | E17: 1802508 | H17: =AVERAGE(C12:C16) -> 6574345.2 | I17: =AVERAGE(D12:D16) -> 3684997.2 | J17: =AVERAGE(E12:E16) -> 1802508
B20: Sum of OPEX | C20: Column Labels
B21: Row Labels | C21: Depreciation | D21: Other Expenses | E21: Grand Total
B22: 2026 | C22: 106441.19 | D22: 1544283.2 | E22: 1650724.4
B23: 2027 | C23: 169205.91 | D23: 885389.18 | E23: 1054595.1
B24: 2028 | C24: 252308.12 | D24: 902017.04 | E24: 1154325.2
B25: 2029 | C25: 332769.7 | D25: 885243.04 | E25: 1218012.7
B26: 2030 | C26: 435180.49 | D26: 895428.08 | E26: 1330608.6
B27: Grand Total | C27: 1295905.4 | D27: 5112360.5 | E27: 6408266
B29: Row Labels | C29: Sum of OPEX
B30: Depreciation | C30: 1295905.4
B31: Other Expenses | C31: 5112360.5
B32: Grand Total | C32: 6408266
B35: Row Labels | C35: Sum of GP Margin | D35: Sum of NP Margin | E35: Sum of ROCE
B36: 2026 | C36: 0.51054742 | D36: 0.1872455 | E36: 0.17755145
B37: 2027 | C37: 0.5339576 | D37: 0.27884483 | E37: 0.24876107
B38: 2028 | C38: 0.55683089 | D38: 0.28628685 | E38: 0.24663432
B39: 2029 | C39: 0.58319555 | D39: 0.3006514 | E39: 0.27603339
B40: 2030 | C40: 0.6139256 | D40: 0.31301248 | E40: 0.25870266
B41: Grand Total | C41: 2.7984571 | D41: 1.3660411 | E41: 1.2076829
